[2024-08-01T21:35:35.946+0000] {local_task_job_runner.py:120} INFO - ::group::Pre task execution logs
[2024-08-01T21:35:35.975+0000] {taskinstance.py:2076} INFO - Dependencies all met for dep_context=non-requeueable deps ti=<TaskInstance: reddit_dag.print_subreddit_posts manual__2024-08-01T21:35:28.154055+00:00 [queued]>
[2024-08-01T21:35:35.986+0000] {taskinstance.py:2076} INFO - Dependencies all met for dep_context=requeueable deps ti=<TaskInstance: reddit_dag.print_subreddit_posts manual__2024-08-01T21:35:28.154055+00:00 [queued]>
[2024-08-01T21:35:35.987+0000] {taskinstance.py:2306} INFO - Starting attempt 1 of 1
[2024-08-01T21:35:36.015+0000] {taskinstance.py:2330} INFO - Executing <Task(PythonOperator): print_subreddit_posts> on 2024-08-01 21:35:28.154055+00:00
[2024-08-01T21:35:36.019+0000] {standard_task_runner.py:64} INFO - Started process 841 to run task
[2024-08-01T21:35:36.020+0000] {standard_task_runner.py:90} INFO - Running: ['airflow', 'tasks', 'run', 'reddit_dag', 'print_subreddit_posts', 'manual__2024-08-01T21:35:28.154055+00:00', '--job-id', '19', '--raw', '--subdir', 'DAGS_FOLDER/project_dag.py', '--cfg-path', '/tmp/tmp7my60rxc']
[2024-08-01T21:35:36.022+0000] {standard_task_runner.py:91} INFO - Job 19: Subtask print_subreddit_posts
[2024-08-01T21:35:36.080+0000] {task_command.py:426} INFO - Running <TaskInstance: reddit_dag.print_subreddit_posts manual__2024-08-01T21:35:28.154055+00:00 [running]> on host a520ee17329b
[2024-08-01T21:35:36.183+0000] {taskinstance.py:2648} INFO - Exporting env vars: AIRFLOW_CTX_DAG_OWNER='airflow' AIRFLOW_CTX_DAG_ID='reddit_dag' AIRFLOW_CTX_TASK_ID='print_subreddit_posts' AIRFLOW_CTX_EXECUTION_DATE='2024-08-01T21:35:28.154055+00:00' AIRFLOW_CTX_TRY_NUMBER='1' AIRFLOW_CTX_DAG_RUN_ID='manual__2024-08-01T21:35:28.154055+00:00'
[2024-08-01T21:35:36.184+0000] {taskinstance.py:430} INFO - ::endgroup::
[2024-08-01T21:36:07.754+0000] {taskinstance.py:441} INFO - ::group::Post task execution logs
[2024-08-01T21:36:07.756+0000] {taskinstance.py:2905} ERROR - Task failed with exception
Traceback (most recent call last):
  File "/home/airflow/.local/lib/python3.12/site-packages/airflow/models/taskinstance.py", line 465, in _execute_task
    result = _execute_callable(context=context, **execute_callable_kwargs)
             ^^^^^^^^^^^^^^^^^^^^^^^^^^^^^^^^^^^^^^^^^^^^^^^^^^^^^^^^^^^^^
  File "/home/airflow/.local/lib/python3.12/site-packages/airflow/models/taskinstance.py", line 432, in _execute_callable
    return execute_callable(context=context, **execute_callable_kwargs)
           ^^^^^^^^^^^^^^^^^^^^^^^^^^^^^^^^^^^^^^^^^^^^^^^^^^^^^^^^^^^^
  File "/home/airflow/.local/lib/python3.12/site-packages/airflow/models/baseoperator.py", line 401, in wrapper
    return func(self, *args, **kwargs)
           ^^^^^^^^^^^^^^^^^^^^^^^^^^^
  File "/home/airflow/.local/lib/python3.12/site-packages/airflow/operators/python.py", line 235, in execute
    return_value = self.execute_callable()
                   ^^^^^^^^^^^^^^^^^^^^^^^
  File "/home/airflow/.local/lib/python3.12/site-packages/airflow/operators/python.py", line 252, in execute_callable
    return self.python_callable(*self.op_args, **self.op_kwargs)
           ^^^^^^^^^^^^^^^^^^^^^^^^^^^^^^^^^^^^^^^^^^^^^^^^^^^^^
  File "/opt/airflow/dags/project_dag.py", line 39, in scrape
    collection.insert_one(post_data)
  File "/home/airflow/.local/lib/python3.12/site-packages/pymongo/collection.py", line 658, in insert_one
    self._insert_one(
  File "/home/airflow/.local/lib/python3.12/site-packages/pymongo/collection.py", line 598, in _insert_one
    self.__database.client._retryable_write(
  File "/home/airflow/.local/lib/python3.12/site-packages/pymongo/mongo_client.py", line 1575, in _retryable_write
    return self._retry_with_session(retryable, func, s, bulk, operation, operation_id)
           ^^^^^^^^^^^^^^^^^^^^^^^^^^^^^^^^^^^^^^^^^^^^^^^^^^^^^^^^^^^^^^^^^^^^^^^^^^^
  File "/home/airflow/.local/lib/python3.12/site-packages/pymongo/mongo_client.py", line 1461, in _retry_with_session
    return self._retry_internal(
           ^^^^^^^^^^^^^^^^^^^^^
  File "/home/airflow/.local/lib/python3.12/site-packages/pymongo/_csot.py", line 108, in csot_wrapper
    return func(self, *args, **kwargs)
           ^^^^^^^^^^^^^^^^^^^^^^^^^^^
  File "/home/airflow/.local/lib/python3.12/site-packages/pymongo/mongo_client.py", line 1507, in _retry_internal
    ).run()
      ^^^^^
  File "/home/airflow/.local/lib/python3.12/site-packages/pymongo/mongo_client.py", line 2353, in run
    return self._read() if self._is_read else self._write()
                                              ^^^^^^^^^^^^^
  File "/home/airflow/.local/lib/python3.12/site-packages/pymongo/mongo_client.py", line 2456, in _write
    self._server = self._get_server()
                   ^^^^^^^^^^^^^^^^^^
  File "/home/airflow/.local/lib/python3.12/site-packages/pymongo/mongo_client.py", line 2439, in _get_server
    return self._client._select_server(
           ^^^^^^^^^^^^^^^^^^^^^^^^^^^^
  File "/home/airflow/.local/lib/python3.12/site-packages/pymongo/mongo_client.py", line 1322, in _select_server
    server = topology.select_server(
             ^^^^^^^^^^^^^^^^^^^^^^^
  File "/home/airflow/.local/lib/python3.12/site-packages/pymongo/topology.py", line 368, in select_server
    server = self._select_server(
             ^^^^^^^^^^^^^^^^^^^^
  File "/home/airflow/.local/lib/python3.12/site-packages/pymongo/topology.py", line 346, in _select_server
    servers = self.select_servers(
              ^^^^^^^^^^^^^^^^^^^^
  File "/home/airflow/.local/lib/python3.12/site-packages/pymongo/topology.py", line 253, in select_servers
    server_descriptions = self._select_servers_loop(
                          ^^^^^^^^^^^^^^^^^^^^^^^^^^
  File "/home/airflow/.local/lib/python3.12/site-packages/pymongo/topology.py", line 303, in _select_servers_loop
    raise ServerSelectionTimeoutError(
pymongo.errors.ServerSelectionTimeoutError: localhost:27017: [Errno 111] Connection refused (configured timeouts: socketTimeoutMS: 20000.0ms, connectTimeoutMS: 20000.0ms), Timeout: 30s, Topology Description: <TopologyDescription id: 66abffa846e3d5148394ff96, topology_type: Unknown, servers: [<ServerDescription ('localhost', 27017) server_type: Unknown, rtt: None, error=AutoReconnect('localhost:27017: [Errno 111] Connection refused (configured timeouts: socketTimeoutMS: 20000.0ms, connectTimeoutMS: 20000.0ms)')>]>
[2024-08-01T21:36:07.770+0000] {taskinstance.py:1206} INFO - Marking task as FAILED. dag_id=reddit_dag, task_id=print_subreddit_posts, run_id=manual__2024-08-01T21:35:28.154055+00:00, execution_date=20240801T213528, start_date=20240801T213535, end_date=20240801T213607
[2024-08-01T21:36:07.798+0000] {standard_task_runner.py:110} ERROR - Failed to execute job 19 for task print_subreddit_posts (localhost:27017: [Errno 111] Connection refused (configured timeouts: socketTimeoutMS: 20000.0ms, connectTimeoutMS: 20000.0ms), Timeout: 30s, Topology Description: <TopologyDescription id: 66abffa846e3d5148394ff96, topology_type: Unknown, servers: [<ServerDescription ('localhost', 27017) server_type: Unknown, rtt: None, error=AutoReconnect('localhost:27017: [Errno 111] Connection refused (configured timeouts: socketTimeoutMS: 20000.0ms, connectTimeoutMS: 20000.0ms)')>]>; 841)
[2024-08-01T21:36:07.836+0000] {local_task_job_runner.py:243} INFO - Task exited with return code 1
[2024-08-01T21:36:07.853+0000] {taskinstance.py:3503} INFO - 0 downstream tasks scheduled from follow-on schedule check
[2024-08-01T21:36:07.854+0000] {local_task_job_runner.py:222} INFO - ::endgroup::
