[2024-08-02T18:07:45.252+0000] {local_task_job_runner.py:120} INFO - ::group::Pre task execution logs
[2024-08-02T18:07:45.285+0000] {taskinstance.py:2076} INFO - Dependencies all met for dep_context=non-requeueable deps ti=<TaskInstance: reddit_dag.send_email manual__2024-08-02T18:07:19.238321+00:00 [queued]>
[2024-08-02T18:07:45.298+0000] {taskinstance.py:2076} INFO - Dependencies all met for dep_context=requeueable deps ti=<TaskInstance: reddit_dag.send_email manual__2024-08-02T18:07:19.238321+00:00 [queued]>
[2024-08-02T18:07:45.299+0000] {taskinstance.py:2306} INFO - Starting attempt 1 of 1
[2024-08-02T18:07:45.328+0000] {taskinstance.py:2330} INFO - Executing <Task(EmailOperator): send_email> on 2024-08-02 18:07:19.238321+00:00
[2024-08-02T18:07:45.332+0000] {standard_task_runner.py:64} INFO - Started process 249 to run task
[2024-08-02T18:07:45.334+0000] {standard_task_runner.py:90} INFO - Running: ['airflow', 'tasks', 'run', 'reddit_dag', 'send_email', 'manual__2024-08-02T18:07:19.238321+00:00', '--job-id', '219', '--raw', '--subdir', 'DAGS_FOLDER/project_dag.py', '--cfg-path', '/tmp/tmpjei__fmc']
[2024-08-02T18:07:45.335+0000] {standard_task_runner.py:91} INFO - Job 219: Subtask send_email
[2024-08-02T18:07:45.395+0000] {task_command.py:426} INFO - Running <TaskInstance: reddit_dag.send_email manual__2024-08-02T18:07:19.238321+00:00 [running]> on host 7df8ffa41b22
[2024-08-02T18:07:45.496+0000] {taskinstance.py:2648} INFO - Exporting env vars: AIRFLOW_CTX_DAG_OWNER='airflow' AIRFLOW_CTX_DAG_ID='reddit_dag' AIRFLOW_CTX_TASK_ID='send_email' AIRFLOW_CTX_EXECUTION_DATE='2024-08-02T18:07:19.238321+00:00' AIRFLOW_CTX_TRY_NUMBER='1' AIRFLOW_CTX_DAG_RUN_ID='manual__2024-08-02T18:07:19.238321+00:00'
[2024-08-02T18:07:45.497+0000] {taskinstance.py:430} INFO - ::endgroup::
[2024-08-02T18:07:45.524+0000] {logging_mixin.py:188} WARNING - /home/airflow/.local/lib/python3.12/site-packages/airflow/utils/email.py:154 RemovedInAirflow3Warning: Fetching SMTP credentials from configuration variables will be deprecated in a future release. Please set credentials using a connection instead.
[2024-08-02T18:07:45.525+0000] {email.py:271} INFO - Email alerting: attempt 1
[2024-08-02T18:08:06.571+0000] {taskinstance.py:441} INFO - ::group::Post task execution logs
[2024-08-02T18:08:06.572+0000] {taskinstance.py:2905} ERROR - Task failed with exception
Traceback (most recent call last):
  File "/home/airflow/.local/lib/python3.12/site-packages/airflow/models/taskinstance.py", line 465, in _execute_task
    result = _execute_callable(context=context, **execute_callable_kwargs)
             ^^^^^^^^^^^^^^^^^^^^^^^^^^^^^^^^^^^^^^^^^^^^^^^^^^^^^^^^^^^^^
  File "/home/airflow/.local/lib/python3.12/site-packages/airflow/models/taskinstance.py", line 432, in _execute_callable
    return execute_callable(context=context, **execute_callable_kwargs)
           ^^^^^^^^^^^^^^^^^^^^^^^^^^^^^^^^^^^^^^^^^^^^^^^^^^^^^^^^^^^^
  File "/home/airflow/.local/lib/python3.12/site-packages/airflow/models/baseoperator.py", line 401, in wrapper
    return func(self, *args, **kwargs)
           ^^^^^^^^^^^^^^^^^^^^^^^^^^^
  File "/home/airflow/.local/lib/python3.12/site-packages/airflow/operators/email.py", line 79, in execute
    send_email(
  File "/home/airflow/.local/lib/python3.12/site-packages/airflow/utils/email.py", line 80, in send_email
    return backend(
           ^^^^^^^^
  File "/home/airflow/.local/lib/python3.12/site-packages/airflow/utils/email.py", line 154, in send_email_smtp
    send_mime_email(e_from=mail_from, e_to=recipients, mime_msg=msg, conn_id=conn_id, dryrun=dryrun)
  File "/home/airflow/.local/lib/python3.12/site-packages/airflow/utils/email.py", line 273, in send_mime_email
    smtp_conn = _get_smtp_connection(smtp_host, smtp_port, smtp_timeout, smtp_ssl)
                ^^^^^^^^^^^^^^^^^^^^^^^^^^^^^^^^^^^^^^^^^^^^^^^^^^^^^^^^^^^^^^^^^^
  File "/home/airflow/.local/lib/python3.12/site-packages/airflow/utils/email.py", line 317, in _get_smtp_connection
    return smtplib.SMTP(host=host, port=port, timeout=timeout)
           ^^^^^^^^^^^^^^^^^^^^^^^^^^^^^^^^^^^^^^^^^^^^^^^^^^^
  File "/usr/local/lib/python3.12/smtplib.py", line 255, in __init__
    (code, msg) = self.connect(host, port)
                  ^^^^^^^^^^^^^^^^^^^^^^^^
  File "/usr/local/lib/python3.12/smtplib.py", line 341, in connect
    self.sock = self._get_socket(host, port, self.timeout)
                ^^^^^^^^^^^^^^^^^^^^^^^^^^^^^^^^^^^^^^^^^^
  File "/usr/local/lib/python3.12/smtplib.py", line 312, in _get_socket
    return socket.create_connection((host, port), timeout,
           ^^^^^^^^^^^^^^^^^^^^^^^^^^^^^^^^^^^^^^^^^^^^^^^
  File "/usr/local/lib/python3.12/socket.py", line 853, in create_connection
    raise exceptions[0]
  File "/usr/local/lib/python3.12/socket.py", line 838, in create_connection
    sock.connect(sa)
ConnectionRefusedError: [Errno 111] Connection refused
[2024-08-02T18:08:06.585+0000] {taskinstance.py:1206} INFO - Marking task as FAILED. dag_id=reddit_dag, task_id=send_email, run_id=manual__2024-08-02T18:07:19.238321+00:00, execution_date=20240802T180719, start_date=20240802T180745, end_date=20240802T180806
[2024-08-02T18:08:06.612+0000] {standard_task_runner.py:110} ERROR - Failed to execute job 219 for task send_email ([Errno 111] Connection refused; 249)
[2024-08-02T18:08:06.654+0000] {local_task_job_runner.py:243} INFO - Task exited with return code 1
[2024-08-02T18:08:06.671+0000] {taskinstance.py:3503} INFO - 0 downstream tasks scheduled from follow-on schedule check
[2024-08-02T18:08:06.673+0000] {local_task_job_runner.py:222} INFO - ::endgroup::
