[2024-08-01T22:18:43.713+0000] {local_task_job_runner.py:120} INFO - ::group::Pre task execution logs
[2024-08-01T22:18:43.742+0000] {taskinstance.py:2076} INFO - Dependencies all met for dep_context=non-requeueable deps ti=<TaskInstance: reddit_dag.processing manual__2024-08-01T22:18:30.492837+00:00 [queued]>
[2024-08-01T22:18:43.754+0000] {taskinstance.py:2076} INFO - Dependencies all met for dep_context=requeueable deps ti=<TaskInstance: reddit_dag.processing manual__2024-08-01T22:18:30.492837+00:00 [queued]>
[2024-08-01T22:18:43.754+0000] {taskinstance.py:2306} INFO - Starting attempt 1 of 1
[2024-08-01T22:18:43.782+0000] {taskinstance.py:2330} INFO - Executing <Task(PythonOperator): processing> on 2024-08-01 22:18:30.492837+00:00
[2024-08-01T22:18:43.786+0000] {standard_task_runner.py:64} INFO - Started process 1741 to run task
[2024-08-01T22:18:43.788+0000] {standard_task_runner.py:90} INFO - Running: ['airflow', 'tasks', 'run', 'reddit_dag', 'processing', 'manual__2024-08-01T22:18:30.492837+00:00', '--job-id', '51', '--raw', '--subdir', 'DAGS_FOLDER/project_dag.py', '--cfg-path', '/tmp/tmpzsptv9d3']
[2024-08-01T22:18:43.789+0000] {standard_task_runner.py:91} INFO - Job 51: Subtask processing
[2024-08-01T22:18:43.847+0000] {task_command.py:426} INFO - Running <TaskInstance: reddit_dag.processing manual__2024-08-01T22:18:30.492837+00:00 [running]> on host a520ee17329b
[2024-08-01T22:18:43.958+0000] {taskinstance.py:2648} INFO - Exporting env vars: AIRFLOW_CTX_DAG_OWNER='airflow' AIRFLOW_CTX_DAG_ID='reddit_dag' AIRFLOW_CTX_TASK_ID='processing' AIRFLOW_CTX_EXECUTION_DATE='2024-08-01T22:18:30.492837+00:00' AIRFLOW_CTX_TRY_NUMBER='1' AIRFLOW_CTX_DAG_RUN_ID='manual__2024-08-01T22:18:30.492837+00:00'
[2024-08-01T22:18:43.959+0000] {taskinstance.py:430} INFO - ::endgroup::
[2024-08-01T22:18:43.983+0000] {taskinstance.py:441} INFO - ::group::Post task execution logs
[2024-08-01T22:18:43.984+0000] {taskinstance.py:2905} ERROR - Task failed with exception
Traceback (most recent call last):
  File "/home/airflow/.local/lib/python3.12/site-packages/airflow/models/taskinstance.py", line 465, in _execute_task
    result = _execute_callable(context=context, **execute_callable_kwargs)
             ^^^^^^^^^^^^^^^^^^^^^^^^^^^^^^^^^^^^^^^^^^^^^^^^^^^^^^^^^^^^^
  File "/home/airflow/.local/lib/python3.12/site-packages/airflow/models/taskinstance.py", line 432, in _execute_callable
    return execute_callable(context=context, **execute_callable_kwargs)
           ^^^^^^^^^^^^^^^^^^^^^^^^^^^^^^^^^^^^^^^^^^^^^^^^^^^^^^^^^^^^
  File "/home/airflow/.local/lib/python3.12/site-packages/airflow/models/baseoperator.py", line 401, in wrapper
    return func(self, *args, **kwargs)
           ^^^^^^^^^^^^^^^^^^^^^^^^^^^
  File "/home/airflow/.local/lib/python3.12/site-packages/airflow/operators/python.py", line 235, in execute
    return_value = self.execute_callable()
                   ^^^^^^^^^^^^^^^^^^^^^^^
  File "/home/airflow/.local/lib/python3.12/site-packages/airflow/operators/python.py", line 252, in execute_callable
    return self.python_callable(*self.op_args, **self.op_kwargs)
           ^^^^^^^^^^^^^^^^^^^^^^^^^^^^^^^^^^^^^^^^^^^^^^^^^^^^^
  File "/opt/airflow/dags/project_dag.py", line 57, in processing
    for submission in most_upvoted_post:
  File "/home/airflow/.local/lib/python3.12/site-packages/pymongo/cursor.py", line 1243, in next
    if len(self.__data) or self._refresh():
                           ^^^^^^^^^^^^^^^
  File "/home/airflow/.local/lib/python3.12/site-packages/pymongo/cursor.py", line 1160, in _refresh
    self.__send_message(q)
  File "/home/airflow/.local/lib/python3.12/site-packages/pymongo/cursor.py", line 1039, in __send_message
    response = client._run_operation(
               ^^^^^^^^^^^^^^^^^^^^^^
  File "/home/airflow/.local/lib/python3.12/site-packages/pymongo/_csot.py", line 108, in csot_wrapper
    return func(self, *args, **kwargs)
           ^^^^^^^^^^^^^^^^^^^^^^^^^^^
  File "/home/airflow/.local/lib/python3.12/site-packages/pymongo/mongo_client.py", line 1431, in _run_operation
    return self._retryable_read(
           ^^^^^^^^^^^^^^^^^^^^^
  File "/home/airflow/.local/lib/python3.12/site-packages/pymongo/mongo_client.py", line 1540, in _retryable_read
    return self._retry_internal(
           ^^^^^^^^^^^^^^^^^^^^^
  File "/home/airflow/.local/lib/python3.12/site-packages/pymongo/_csot.py", line 108, in csot_wrapper
    return func(self, *args, **kwargs)
           ^^^^^^^^^^^^^^^^^^^^^^^^^^^
  File "/home/airflow/.local/lib/python3.12/site-packages/pymongo/mongo_client.py", line 1507, in _retry_internal
    ).run()
      ^^^^^
  File "/home/airflow/.local/lib/python3.12/site-packages/pymongo/mongo_client.py", line 2353, in run
    return self._read() if self._is_read else self._write()
           ^^^^^^^^^^^^
  File "/home/airflow/.local/lib/python3.12/site-packages/pymongo/mongo_client.py", line 2483, in _read
    self._server = self._get_server()
                   ^^^^^^^^^^^^^^^^^^
  File "/home/airflow/.local/lib/python3.12/site-packages/pymongo/mongo_client.py", line 2439, in _get_server
    return self._client._select_server(
           ^^^^^^^^^^^^^^^^^^^^^^^^^^^^
  File "/home/airflow/.local/lib/python3.12/site-packages/pymongo/mongo_client.py", line 1322, in _select_server
    server = topology.select_server(
             ^^^^^^^^^^^^^^^^^^^^^^^
  File "/home/airflow/.local/lib/python3.12/site-packages/pymongo/topology.py", line 368, in select_server
    server = self._select_server(
             ^^^^^^^^^^^^^^^^^^^^
  File "/home/airflow/.local/lib/python3.12/site-packages/pymongo/topology.py", line 346, in _select_server
    servers = self.select_servers(
              ^^^^^^^^^^^^^^^^^^^^
  File "/home/airflow/.local/lib/python3.12/site-packages/pymongo/topology.py", line 253, in select_servers
    server_descriptions = self._select_servers_loop(
                          ^^^^^^^^^^^^^^^^^^^^^^^^^^
  File "/home/airflow/.local/lib/python3.12/site-packages/pymongo/topology.py", line 320, in _select_servers_loop
    self._ensure_opened()
  File "/home/airflow/.local/lib/python3.12/site-packages/pymongo/topology.py", line 694, in _ensure_opened
    raise InvalidOperation("Cannot use MongoClient after close")
pymongo.errors.InvalidOperation: Cannot use MongoClient after close
[2024-08-01T22:18:44.001+0000] {taskinstance.py:1206} INFO - Marking task as FAILED. dag_id=reddit_dag, task_id=processing, run_id=manual__2024-08-01T22:18:30.492837+00:00, execution_date=20240801T221830, start_date=20240801T221843, end_date=20240801T221844
[2024-08-01T22:18:44.029+0000] {standard_task_runner.py:110} ERROR - Failed to execute job 51 for task processing (Cannot use MongoClient after close; 1741)
[2024-08-01T22:18:44.042+0000] {local_task_job_runner.py:243} INFO - Task exited with return code 1
[2024-08-01T22:18:44.060+0000] {taskinstance.py:3503} INFO - 0 downstream tasks scheduled from follow-on schedule check
[2024-08-01T22:18:44.062+0000] {local_task_job_runner.py:222} INFO - ::endgroup::
